Workbook

Sheet 단원별DB
A1: 영역 | B1: 세부단원 | C1: 구분 | D1: 순위 | E1: 가중치 | F1: Q번호 | G1: 문제 | H1: 핵심어 | I1: 시험용 답안 | J1: 평균배점 | K1: 출제회차 | L1: 분류
A2: A 기초심리평가 | B2: MMPI·다면적 인성검사 | C2: 메인 | D2: 4 | E2: 9.39 | F2: Q71 | G2: MMPI 상승 분석에서 4-9/9-4 형태에 대한 해석 5가지를 쓰시오. | H2: 반사회적 행동화 · 충동성·공격성 · 피상적 대인관계 · 무책임·규범 무시 · 합리화 방어 | I2: ① *반사회적·성적 행동화*: 범법·신체노출·성적 일탈 등 행동화 위험이 높다. ② *충동성·공격성*: 충동 조절이 어렵고 과격·공격적 행동을 보인다. ③ *피상적 대인관계*: 자기중심적이고 타인을 불신해 관계가 깊지 못하다. ④ *무책임·규범 무시*: 행동에 무책임하며 사회규범·가치를 무시한다. ⑤ *합리화 방어*: 합리화로 문제를 외면하고 실패 원인을 타인에게 전가한다. | J2: 5 | K2: 2006 2008 2011 2015 2017-1회 2020-1회 2021-1회 2023-2회 2024-1회 2025-3회 | L2: PDF확정
A3: A 기초심리평가 | B3: MMPI·다면적 인성검사 | C3: 메인 | D3: 25 | E3: 4.55 | F3: Q70 | G3: MMPI-2 척도에서 6-8/8-6유형의 일반적인 특성 5가지와 가능성 있는 장애 진단명 2가지를 쓰시오. | H3: 낮은 자존감·열등감 · 적대감·의심 · 현실검증력 저하 · 정서 둔마·부적절 · 정신증 증상 · 조현병 · 분열성·편집성 성격장애 | I3: [특성 5] ① *낮은 자존감·열등감·죄책감*. ② *적대감·의심, 불안정한 대인관계*. ③ *현실검증력 저하*로 자폐적·분열적 사고. ④ *정서 둔마·부적절한 정동, 우울*. ⑤ *피해·과대망상·환청 등 정신증 증상*. [진단 2] *조현병(편집형 포함)* / *조현성(분열성)·편집성 성격장애*. | K3: 2007 2010 2016-2회 2022-3회 2025-2회 | L3: PDF확정
A4: A 기초심리평가 | B4: MMPI·다면적 인성검사 | C4: 메인 | D4: 30 | E4: 4.04 | F4: Q74 | G4: MMPI-2의 성격병리 5요인 척도(PSY-5 척도)를 쓰시오. | H4: 공격성(AGGR) · 정신증(PSYC) · 통제결여(DISC) · 부정적 정서성/신경증(NEGE) · 내향성/낮은 긍정정서(INTR) | I4: ① *공격성(AGGR)* ② *정신증(PSYC)* ③ *통제결여(DISC)* ④ *부정적 정서성/신경증(NEGE)* ⑤ *내향성/낮은 긍정적 정서성(INTR)* | J4: 5 | K4: 2018-3회 2021-3회 2026-1회 | L4: PDF확정
A5: A 기초심리평가 | B5: MMPI·다면적 인성검사 | C5: 메인 | D5: 39 | E5: 3.54 | F5: Q67 | G5: 타당도 척도 L, K 30 이하/ F 70 이상일 때 유형 2가지를 쓰시오. | H5: 곤란 인정·해결능력 결여 · 증상 과장·위장(부정왜곡) | I5: ① *곤란 인정·해결능력 결여*: 정서·신체적 곤란은 인정하나 스스로 해결할 자신·능력이 없다. ② *증상 과장·위장*: 도움을 얻으려 증상을 과장하거나 장애가 있는 듯 위장한다(부정왜곡/‘fake-bad’). | K5: 2015-1회 2019-3회 2020-1회 2025-1회 | L5: 검토필요
A6: A 기초심리평가 | B6: MMPI·다면적 인성검사 | C6: 메인 | D6: 49 | E6: 2.94 | F6: Q107 | G6: 아동 평가에서 특정 문제영역이 아닌 전반적인 광범위한 문제영역에 대해 보호자의 보고를 토대로 평가할 수 있는 평정 척도가 있다. 그에 해당하는 평정 척도 2가지를 쓰시오. | H6: K-CBCL(아동·청소년 행동평가척도) · KPRC(아동인성평정척도) | I6: ① *K-CBCL(아동·청소년 행동평가척도)*: 보호자 보고로 정서·행동 문제를 광범위하게 평가한다. ② *KPRC(한국 아동인성평정척도)*: 보호자 보고로 아동의 전반적 정신건강·적응을 평가한다. | K6: 2012 2017-2회 2020-1회 2024-3회 | L6: PDF확정
A7: A 기초심리평가 | B7: MMPI·다면적 인성검사 | C7: 메인 | D7: 51 | E7: 2.89 | F7: Q86 | G7: MMPI나 BDI 같은 자기 보고형 객관적 심리검사의 장점과 단점을 3가지씩 쓰시오. | H7: 실시 간편 · 높은 신뢰도·타당도 · 객관성 · 사회적 바람직성 · 반응 경향성 · 문항내용 제한성 | I7: [장점] ① *실시·채점의 간편성*. ② *높은 신뢰도·타당도*. ③ *객관성 증대*. [단점] ① *사회적 바람직성*(좋게 보이려는 응답). ② *반응 경향성*(묵종 등 일관된 편향). ③ *문항내용의 제한성*. | J7: 5 | K7: 2009 2017-2회 2022-1회 2024-2회 | L7: 검토필요
A8: A 기초심리평가 | B8: MMPI·다면적 인성검사 | C8: 메인 | D8: 89 | E8: 2.13 | F8: Q65 | G8: MMPI 결과 T 점수로 L 척도 48, F 척도 110, K 척도 45를 보이고 5번 척도를 제외한 대부분의 임 상 척도가 높게 상승하였다. 이런 프로파일을 보일 가능성이 있는 사람들의 유형을 3가지 쓰시오. | H8: 증상 과장(관심·도움 추구) · 검사 저항·반항 · 책임 회피·기만 | I8: ① *증상 과장형*: 문제를 과장해 주위 관심·도움을 얻으려는 사람. ② *저항·반항형*: 검사·검사자에게 저항적·반항적 태도를 보이는 사람. ③ *회피·기만형*: 책임을 회피하거나 타인을 기만하려는 사람. (F척도 극단 상승=‘fake-bad’ 프로파일) | K8: 2009 2020-3회 2024-1회 | L8: PDF확정
A9: A 기초심리평가 | B9: MMPI·다면적 인성검사 | C9: 메인 | D9: 92 | E9: 1.91 | F9: Q68 | G9: MMPI 6번 척도가 T 점수 72점이 나왔다면 이는 임상적으로 어떤 의미인지 5가지를 제시하시오. | H9: 대인관계 예민성 · 피해의식 · 만연한 의심 · 경직된 사고 · 관계망상 | I9: ① *대인관계 예민성*. ② *피해의식*. ③ *만연한 의심*. ④ *경직된 사고*. ⑤ *관계망상* 경향. (MMPI 6번 Pa척도 상승의 의미) | J9: 5 | K9: 2003 2005 2015 2020-1회 | L9: PDF확정
A10: A 기초심리평가 | B10: MMPI·다면적 인성검사 | C10: 확장 | D10: 108 | E10: 1.77 | F10: Q75 | G10: MMPI-2 재구성 임상 척도 중 다른 사람들이 믿을만하지 못하고 남을 배려하지 않고 자신만 생각하 며 착취적이라고 생각하는 경우 상승하는 척도를 쓰시오. | H10: RC3 냉소적 태도(Cynicism) | I10: *RC3 — 냉소적 태도(Cynicism)*: 타인을 믿을 수 없고 이기적·착취적이라고 보는 냉소적 신념이 상승한다. | J10: 3 | K10: 2020-2회 2025-1회 | L10: PDF확정
A11: A 기초심리평가 | B11: MMPI·다면적 인성검사 | C11: 확장 | D11: 110 | E11: 1.77 | F11: Q170 | G11: 순환성 장애(Cyclothymic Disorder)의 진단기준을 3가지 쓰시오. | H11: 경조증·우울증상 2년(아동 1년) 지속 · 증상 없는 기간 2개월 이내 · 주요우울·조증·경조증삽화 없음 | I11: ① *경조증·우울 증상*이 삽화 기준엔 못 미치며 *성인 2년(아동·청소년 1년) 이상 지속*된다. ② 그 기간 *절반 이상 증상*이 있고 *증상 없는 기간이 2개월을 넘지 않는다*. ③ *주요우울·조증·경조증 삽화를 경험한 적이 없다*. (추가) 정신병적 장애·물질로 설명되지 않는다. | J11: 6 | K11: 2018-3회 2025-1회 | L11: PDF확정
A12: A 기초심리평가 | B12: MMPI·다면적 인성검사 | C12: 확장 | D12: 116 | E12: 1.69 | F12: Q62 | G12: MMPI-2에서 ?(무응답)척도가 상승하는 경우를 5가지 쓰시오. | H12: 강박적 정확성 · 부주의·혼란 누락 · 방어적 자기노출 거부 · 비협조·반항 · 극도의 불안·우울 | I12: ① *강박적 태도*: 지나치게 정확히 답하려다 누락한다. ② *부주의·혼란*으로 문항을 빠뜨린다. ③ *방어적 태도*: 자기노출을 꺼리거나 검사 불신. ④ *비협조·반항적* 태도. ⑤ *극도의 불안·우울*로 집중하지 못한다. | K12: 2011 2015 2022-3회 | L12: PDF확정
A13: A 기초심리평가 | B13: MMPI·다면적 인성검사 | C13: 확장 | D13: 126 | E13: 1.47 | F13: Q69 | G13: MMPI 9번 척도가 27점일 때 임상적 현상 2가지를 쓰시오. | H13: 무감동·무기력·만성 피로 · 낮은 활력·우울 | I13: ① *무감동·무기력·의욕 저하*, 만성적 피로·무력감을 보인다. ② *활력·활동 수준이 전반적으로 낮고* 우울한 정서·우울증상을 호소한다. (MMPI 9번 Ma척도가 매우 낮을 때의 양상) | J13: 4.5 | K13: 2017-1회 2024-3회 | L13: PDF확정
A14: A 기초심리평가 | B14: MMPI·다면적 인성검사 | C14: 확장 | D14: 157 | E14: 1.23 | F14: Q63 | G14: MMPI에서 과장된 보고에 상승하는 척도 3개를 설명하시오. | H14: F(비전형) · Fb(비전형 후반부) · Fp(비전형 정신병리) | I14: ① *F(비전형 척도)*: 규준집단에서 드문 문항 응답으로 증상 과장을 탐지한다. ② *Fb(비전형 후반부)*: 후반부 문항으로 검사 중 태도 변화·과장을 평가한다. ③ *Fp(비전형 정신병리)*: 실제 환자도 드물게 답하는 문항으로 의도적 부정왜곡을 판별한다. | J14: 4.5 | K14: 2019-3회 2023-1회 | L14: PDF확정
A15: A 기초심리평가 | B15: MMPI·다면적 인성검사 | C15: 확장 | D15: 158 | E15: 1.23 | F15: Q73 | G15: MMPI-2 프로파일에서 가장 우선적으로 다루어야 할 척도는 무엇이고 그 이유를 기술하시오. | H15: 7-8-9 코드 · 정신증·현실검증력 손상 · 급박성·만성화 예방 | I15: 가장 우선 다룰 것은 *7-8-9 상승 프로파일*이다. *정신증적 증상·현실검증력 손상* 가능성이 높아 *망상·위험행동* 위험이 크므로, *조기 정신증의 발견·치료로 만성화를 예방*하기 위해 가장 급박하게 다뤄야 한다. | K15: 2017-1회 2023-1회 | L15: 검토필요
A16: A 기초심리평가 | B16: MMPI·다면적 인성검사 | C16: 확장 | D16: 171 | E16: 0.97 | F16: Q66 | G16: 어떤 환자에게 MMPI를 실시한 결과 L, K가 70이 넘어 방어적 경향이 강한 것으로 나타났고, 검사결 과를 해석할 수 없는 정도였다. 그러나 이 사람에게 심리검사는 꼭 필요한 것으로 판단되었다. 이때 임상심리사가 취할 수 있는 방법을 2가지로 구분해서 설명하시오. | H16: 극단적:해석 보류·유예 · 방어적이나 가능:잠정·제한적 해석 | I16: ① *신뢰성이 극단적으로 결여된 경우*: 임상척도 해석을 *보류·유예*하고 신뢰성 확보 후 재실시한다. ② *방어적이나 해석 가능한 경우*: *방어적 태도를 충분히 고려해 잠정적·제한적으로* 임상척도를 해석한다. | K16: 2018-1회 2020-3회 | L16: 검토필요
A17: A 기초심리평가 | B17: MMPI·다면적 인성검사 | C17: 확장 | D17: 176 | E17: 0.96 | F17: Q58 | G17: MMPI-2에서 재구성 임상 척도를 개발하게 된 이유를 설명하시오. | H17: 기존 임상척도 문항 타당성 문제 · 척도 간 높은 상관·차별 해석 곤란 | I17: 기존 임상척도는 *문항 타당성 문제로 상승의 의미가 불분명*하고 *척도 간 상관이 높아 차별적 해석이 어려웠다*. 이를 보완해 핵심 차원을 분리·정련하고자 *재구성 임상척도(RC)*가 개발되었다. | J17: 4.5 | K17: 2016-1회 2020-2회 | L17: 검토필요
A18: A 기초심리평가 | B18: MMPI·다면적 인성검사 | C18: 확장 | D18: 191 | E18: 0.87 | F18: Q79 | G18: 다음은 38세 미혼여성의 MMPI의 검사결과이다. 이를 토대로 수검자의 임상적 특징, 가능한 진단명, 주로 사용하는 방어기제에 대해 간략하게 기술하시오. | H18: V형(방어적) · 1-3 상승(신체화·전환) · 전환장애 · 부인·억압 | I18: (임상특징) 타당도 *V형(방어적, L·K↑ F↓)*, 임상 *1-3 상승(신체화·전환 경향)*. (가능 진단) *전환장애*(신체증상 및 관련 장애). (주 방어기제) *부인·억압*. | K18: 2012 2018-3회 | L18: 검토필요
A19: A 기초심리평가 | B19: MMPI·다면적 인성검사 | C19: 확장 | D19: 206 | E19: 0.63 | F19: Q77 | G19: MMPI-2 척도의 2개인 편집증, 경조증에 대해 쓰시오. | H19: 6번 편집증(피해의식·의심·관계망상) · 9번 경조증(고양된 기분·사고비약·과활동) | I19: ① *6번 편집증(Pa)*: 대인 예민성·피해의식·만연한 의심·경직된 사고·관계망상. ② *9번 경조증(Ma)*: 고양된 기분·빠른 말과 행동·사고 비약·이자극성(화를 잘 냄). | K19: 2023-3회 | L19: 검토필요
A20: A 기초심리평가 | B20: MMPI·다면적 인성검사 | C20: 확장 | D20: 207 | E20: 0.62 | F20: Q76 | G20: MMPI 검사의 임상척도 중 편집증 척도의 임상 소척도 3가지를 쓰고 설명하시오. | H20: Pa1 피해의식 · Pa2 예민성 · Pa3 순진성 | I20: ① *Pa1 피해의식*: 외부의 부당한 대우·피해를 지각한다. ② *Pa2 예민성*: 정서적으로 과민하고 긴장한다. ③ *Pa3 순진성(도덕적 미덕)*: 타인을 지나치게 신뢰·낙관하며 적대감을 부인한다. | J20: 4.3 | K20: 2023-2회 | L20: 검토필요
A21: A 기초심리평가 | B21: MMPI·다면적 인성검사 | C21: 확장 | D21: 220 | E21: 0.46 | F21: Q64 | G21: MMPI의 타당도 척도에서 긍정왜곡과 부정왜곡에 대해 설명하시오. | H21: 긍정왜곡(V형,L·K↑F↓,문제 부인) · 부정왜곡(삿갓형,F↑K↓,증상 과장) | I21: ① *긍정왜곡*: 문제를 부인·최소화한다 → *V형(L·K↑, F↓)*, 자신을 좋게 보이려 한다. ② *부정왜곡*: 심한 장애가 있는 것처럼 보이려 한다 → *삿갓형(F↑, K↓)*, 증상 과장·도움 요청(꾀병 가능성). | K21: 2019-3회 | L21: 검토필요
A22: A 기초심리평가 | B22: MMPI·다면적 인성검사 | C22: 확장 | D22: 226 | E22: 0.42 | F22: Q72 | G22: MMPI 4, 6번 척도가 상승되어 있고 척도 5가 이들 척도보다 10점 이상 낮거나 T 점수가 50점 이하 로 하락되어 있는 형태의 명칭을 쓰시오. | H22: 수동-공격성 V(Passive-Aggressive V) | I22: *수동-공격성 V형(Passive-Aggressive V)*: 4·6번이 상승하고 5번이 그보다 10점 이상 낮은(또는 T50 이하) 형태로, 표면적 순응 이면에 적대·공격성이 잠재한다. | K22: 2017-2회 | L22: 검토필요
A23: A 기초심리평가 | B23: MMPI·다면적 인성검사 | C23: 확장 | D23: 231 | E23: 0.4 | F23: Q59 | G23: MMPI-2에서 이상으로 간주하는 점수와 그 이유에 대해서 설명하시오. | H23: T 65 이상 · 재표준화로 평균 하향(원판 70T 해당) | I23: *이상 기준: T점수 65 이상*. *이유*: MMPI-2 재표준화로 평균 T가 낮아져, *원판 MMPI의 70T에 해당하는 수준*이 65T이기 때문이다. | K23: 2016-1회 | L23: 검토필요
A24: A 기초심리평가 | B24: MMPI·다면적 인성검사 | C24: 확장 | D24: 237 | E24: 0.39 | F24: Q60 | G24: MMPI의 일반적 해석과정 7단계를 간략히 기술하시오. (단, 타당도척도와 임상척도를 중심으로 기술 할 것) | H24: 검사태도 · 척도별 점수 · 척도간 연관 · 응집·분산 · 낮은 척도 · 형태 분석 · 전체 프로파일 | I24: ① *검사태도 검토*. ② *척도별 점수 검토*. ③ *척도 간 연관성 검토*. ④ *척도 간 응집·분산 분석*. ⑤ *낮은 임상척도 검토*. ⑥ *형태적 분석*. ⑦ *전체 프로파일 형태 분석*. | K24: 2015 | L24: 검토필요
A25: A 기초심리평가 | B25: MMPI·다면적 인성검사 | C25: 확장 | D25: 238 | E25: 0.39 | F25: Q78 | G25: 다음은 20대 남성의 다면적 인성검사의 결과이다. 이 결과를 타당도 척도와 임상 척도의 코드 유형에 근거하여 각각 설명하시오. | H25: 타당(F 상승=고통·도움요청) · 2-7(D-Pt) 불안성 우울 · 우울·불안·강박 가능 | I25: (타당도) 검사 결과는 *타당·해석 가능*하며, F 상승은 *정서적 고통·도움 요청*을 시사한다. (임상·코드) *2-7(D-Pt) 코드유형* — *불안·긴장이 동반된 우울*. *우울장애·불안장애·강박장애* 가능성. | K25: 2015 | L25: 검토필요
A26: A 기초심리평가 | B26: MMPI·다면적 인성검사 | C26: 확장 | D26: 239 | E26: 0.39 | F26: Q81 | G26: 다음 보기의 사례를 읽고 A씨의 MMPI 검사결과에 따라 유추 가능한 진단명과 함께 진단의 이유를 각각 서술하시오. | H26: 꾀병(Malingering) · F↑(112) L·K↓ 부정왜곡 · 6-7-8 동반상승 · 징집 회피 동기 | I26: (진단) *꾀병(Malingering)*. (이유) ① *L·K 낮고 F 매우 높은 전형적 부정왜곡 프로파일*(F112·L38·K36). ② *6·7·8번 동반 상승*은 부정왜곡에서 흔하다. ③ *군 입대 회피라는 외적 동기*와 과대망상 주장 → 의도적 증상 과장(꾀병) 가능성이 높다. | K26: 2015 | L26: 검토필요
A27: A 기초심리평가 | B27: MMPI·다면적 인성검사 | C27: 확장 | D27: 242 | E27: 0.37 | F27: Q61 | G27: MMPI-2의 타당도 척도 4가지를 쓰시오. | H27: ?(무응답) · L(부인) · F(비전형) · K(교정) | I27: ① *?(무응답)*: 누락·양쪽 응답 문항 수로 비협조·반응곤란을 평가. ② *L(부인)*: 지나치게 긍정적으로 보이려는 세련되지 못한 방어. ③ *F(비전형)*: 드문 문항 응답으로 증상 과장·비전형 반응 탐지. ④ *K(교정)*: 미묘·세련된 방어, 병리를 정상으로 보이려는 경향. | J27: 4.3 | K27: 2013 | L27: 검토필요
A28: A 기초심리평가 | B28: MMPI·다면적 인성검사 | C28: 확장 | D28: 257 | E28: 0.32 | F28: Q80 | G28: 다음 사례의 MMPI 검사결과에서 유추되는 임상적 특징 5가지를 기술하시오. | H28: 삿갓형(과대보고·도움요청) · Pt 상승=불안·우울 · Sc=혼란·집중곤란 · Pd·Hy=분노의 신체화 | I28: ① *삿갓형(F↑)*: 고통을 과대 보고하며 도움을 요청한다. ② *불안·우울*: D·Pt 상승으로 불안·우울, 활력 저하. ③ *혼란·집중곤란*: Sc 상승. ④ *분노의 신체화*: Pd·Hy 상승 — 분노가 행동보다 신체증상으로 표출. ⑤ 종합적으로 *불안성 우울·신체화* 양상. | J28: 4 | K28: 2005 | L28: PDF확정
A29: A 기초심리평가 | B29: 기타 성격·진로검사 | C29: 메인 | D29: 23 | E29: 4.7 | F29: Q83 | G29: TCI의 척도를 구성하는 4가지 기질 차원과 3가지 성격 차원을 설명하시오. | H29: 자극추구(NS) · 위험회피(HA) · 사회적민감성(RD) · 인내력(P) · 자율성(SD) · 연대감(CO) · 자기초월(ST) | I29: [기질 4차원] ① *자극추구(NS)*: 새 자극·보상에 행동이 활성화. ② *위험회피(HA)*: 위험·혐오 자극에 행동이 억제·위축. ③ *사회적 민감성(RD)*: 사회적 보상신호(타인 감정)에 민감. ④ *인내력(P)*: 보상이 없어도 행동을 지속. [성격 3차원] ① *자율성(SD)*: 목표 위해 자기 행동을 조절·적응. ② *연대감(CO)*: 자신을 사회 일부로 보고 타인을 수용. ③ *자기초월(ST)*: 자신을 자연·우주의 일부로 느끼는 영적 성향. | K29: 2018-1회 2023-3회 2024-1회 2024-3회 2025-3회 | L29: PDF확정
A30: A 기초심리평가 | B30: 기타 성격·진로검사 | C30: 메인 | D30: 37 | E30: 3.64 | F30: Q108 | G30: 사회성숙도 검사에서 아동발달의 측정영역 6가지를 기술하시오. | H30: 자조 · 이동 · 작업 · 의사소통 · 자기관리 · 사회화 | I30: ① *자조영역* ② *이동영역* ③ *작업영역* ④ *의사소통영역* ⑤ *자기관리영역* ⑥ *사회화영역* (사회성숙도검사 SMS의 6개 측정영역) | K30: 2015 2022-3회 2024-1회 2025-2회 | L30: PDF확정
A31: A 기초심리평가 | B31: 기타 성격·진로검사 | C31: 확장 | D31: 230 | E31: 0.4 | F31: Q84 | G31: 적성검사와 흥미검사의 공통점과 차이점을 설명하시오. | H31: 공통:개인차 측정·자기이해·진로정보 · 적성=수행능력 예측 인지검사 · 흥미=선호·관심 정서검사 | I31: (공통점) 둘 다 *개인차를 측정해 자기이해·진로/직업 선택의 객관적 정보*를 제공한다. (차이점) *적성검사*는 *수행 능력·적응 가능성을 예측하는 인지적 검사*이고, *흥미검사*는 *선호·관심을 파악하는 정서적 성향 검사*이다. | K31: 2016-2회 | L31: 검토필요
A32: A 기초심리평가 | B32: 기타 성격·진로검사 | C32: 확장 | D32: 249 | E32: 0.34 | F32: Q85 | G32: 다음은 심리상담소에서 실시한 A군의 홀랜드 유형 직업 적성검사 결과이다. 이를 토대로 다음에 제시 된 물음에 답하시오. | H32: S-A 유형(사회형-예술형) · 이상직업:상담사·간호사·배우 · 부적합:C·R(회계사·기사) | I32: (1) *S-A 유형(사회형-예술형)*: 사람들과 함께 일하길 선호하고 사회적 영향력을 추구한다. 이상적 직업: *상담사·간호사·사회복지사·연극배우*. (2) 부적합 직업: *C·R 유형*(회계사·통계학자·인쇄기사·엔지니어). | K32: 2009 | L32: 검토필요
A33: A 기초심리평가 | B33: 지능검사 | C33: 메인 | D33: 12 | E33: 6.74 | F33: Q34 | G33: 웩슬러가 정의한 지능의 개념을 쓰고 유동성 지능과 결정성 지능의 특징을 각각 2가지씩 기술하시오. | H33: 합목적적 행동 · 합리적 사고 · 환경의 효율적 처리 · 종합적·전체적 능력 · 유동성:선천·새 문제·노화감소 · 결정성:후천·언어지식·유지 | I33: (개념) 지능은 *합목적적으로 행동*하고 *합리적으로 사고*하며 *환경을 효율적으로 처리*하는 *종합적·전체적 능력*이다(웩슬러). [유동성 지능] ① *선천적·생득적*이며 뇌 성숙에 의존한다. ② *새로운 문제의 추론·처리속도*에 관여하고 *노화에 따라 감소*한다. [결정성 지능] ① *후천적 경험·교육·문화*의 산물이다. ② *언어·지식·이해* 기반으로 *연령이 들어도 유지·증가*한다. | J33: 6 | K33: 2004 2010 2015 2019-3회 2026-1회 | L33: PDF확정
A34: A 기초심리평가 | B34: 지능검사 | C34: 메인 | D34: 60 | E34: 2.73 | F34: Q51 | G34: 웩슬러 지능검사에서 병전지능을 추정할 수 있는 소검사 3가지와 그 이유를 쓰시오. | H34: 어휘 · 상식(기본지식) · 토막짜기 · 변화에 안정적 | I34: ① 소검사: *어휘·상식(기본지식)·토막짜기*. ② 이유: 이 소검사들은 *병이나 상황 변화에 영향을 적게 받아 점수가 안정적*이어서 병전 지능 추정에 적합하다. | J34: 5.2 | K34: 2019-1회 2019-3회 2025-2회 | L34: PDF확정
A35: A 기초심리평가 | B35: 지능검사 | C35: 메인 | D35: 65 | E35: 2.7 | F35: Q38 | G35: K-WAIS-IV의 4가지 주요 지수를 쓰고, 각각에 대해 설명하시오. | H35: 언어이해(VCI) · 지각추론(PRI) · 작업기억(WMI) · 처리속도(PSI) | I35: ① *언어이해지수(VCI)*: 언어적 이해·개념화, 결정성 지식을 반영. ② *지각추론지수(PRI)*: 시각자극 기반 비언어 추론·시공간 문제해결. ③ *작업기억지수(WMI)*: 주의집중 하에 정보를 저장·조작하는 능력. ④ *처리속도지수(PSI)*: 시각정보를 빠르고 정확히 처리하는 정신운동 속도. | J35: 5 | K35: 2016-1회 2026-1회 | L35: 검토필요
A36: A 기초심리평가 | B36: 지능검사 | C36: 메인 | D36: 68 | E36: 2.65 | F36: Q43 | G36: K-WISC-IV의 지표 4가지와 지표별 소검사 1가지씩 쓰시오. | H36: 언어이해-공통성 · 지각추론-토막짜기 · 작업기억-숫자 · 처리속도-기호쓰기 | I36: ① *언어이해(VCI)*: 공통성(또는 어휘·이해). ② *지각추론(PRI)*: 토막짜기(또는 행렬추리·공통그림찾기). ③ *작업기억(WMI)*: 숫자(또는 순차연결). ④ *처리속도(PSI)*: 기호쓰기(또는 동형찾기). | K36: 2023-2회 2024-1회 2025-1회 | L36: PDF확정
A37: A 기초심리평가 | B37: 지능검사 | C37: 메인 | D37: 75 | E37: 2.46 | F37: Q47 | G37: 웩슬러 지능검사의 양적 분석에 포함되어야 할 내용 3가지를 쓰시오. | H37: 현재지능 · 병전지능 · 언어성-동작성 비교 · 소검사 분산 · 강·약점 분석 | I37: ① *현재지능 파악*. ② *병전지능 추정*. ③ *언어성·동작성(또는 지표 간) 비교*. (추가) 소검사 간 점수 분산, 지표 간 강·약점 분석. | J37: 5.2 | K37: 2011 2013 2018-3회 2023-1회 | L37: PDF확정
A38: A 기초심리평가 | B38: 지능검사 | C38: 메인 | D38: 99 | E38: 1.88 | F38: Q101 | G38: 신경심리 평가에서 일반적으로 다루어야 하는 주요 평가영역 6가지를 쓰시오. | H38: 지능 · 기억·학습 · 언어기능 · 주의·처리속도 · 시각구성(시공간) · 집행(실행)기능 | I38: ① *지능*. ② *기억·학습능력*. ③ *언어기능*. ④ *주의력·정신처리속도*. ⑤ *시각구성(시공간)기능*. ⑥ *집행(실행)기능*. | J38: 5 | K38: 2015-2회 2025-3회 | L38: PDF확정
A39: A 기초심리평가 | B39: 지능검사 | C39: 확장 | D39: 115 | E39: 1.69 | F39: Q42 | G39: K-WISC-IV의 핵심 소검사 항목을 모두 쓰시오. | H39: 언어이해(공통성·어휘·이해) · 지각추론(토막짜기·공통그림찾기·행렬추리) · 작업기억(숫자·순차연결) · 처리속도(기호쓰기·동형찾기) | I39: ① *언어이해*: 공통성·어휘·이해 (보충 상식·단어추리). ② *지각추론*: 토막짜기·공통그림찾기·행렬추리 (보충 빠진곳찾기). ③ *작업기억*: 숫자·순차연결 (보충 산수). ④ *처리속도*: 기호쓰기·동형찾기 (보충 선택). | J39: 11 | K39: 2015-1회 2017-1회 2022-3회 | L39: 검토필요
A40: A 기초심리평가 | B40: 지능검사 | C40: 확장 | D40: 119 | E40: 1.66 | F40: Q82 | G40: 다음 사례를 읽고 검사결과 해석을 쓰시오. | H40: 신체화(D·Pt 상승) · 중등도 우울(BDI 23·언어-동작 차) · 감별진단(우울·불안·신체화) | I40: ① *신체화*: 내과 소견 없는 소화불량·불면은 *D(우울)·Pt(불안) 상승*에 따른 심리적 문제의 신체화로 보인다. ② *중등도 우울*: *BDI 23점*과 *언어성-동작성 IQ 31점 차*로 보아 중등도 우울 상태로 판단된다. ③ *감별진단*: *주요우울장애·불안장애·신체화/전환장애*의 감별이 필요하다. | K40: 2003 2007 2008 2017-1회 | L40: 검토필요
...

Sheet 문항전체
A1: 순위 | B1: Q번호 | C1: 가중치 | D1: 누적% | E1: 영역 | F1: 세부단원 | G1: 구분 | H1: 문제 | I1: 핵심어 | J1: 시험용 답안 | K1: 평균배점 | L1: 출제횟수 | M1: 출제회차 | N1: 최신
A2: 1 | B2: Q176 | C2: 16.17 | D2: 3 | E2: B 기초심리상담 | F2: 집단상담 | G2: 메인 | H2: 얄롬(Yalom)이 제시한 집단상담의 치료적 요인을 5가지 기술하시오. | I2: 희망의 고취 · 보편성 · 정보전달 · 이타심 · 1차 가족집단의 교정적 재현 · 사회기술 발달 · 모방행동 · 대인관계 학습 · 집단 응집력 · 정화 · 실존적 요인 | J2: ※ 아래 중 5(또는 6)가지를 기술. ① *희망의 고취*: 다른 집단원의 회복을 보며 자신도 나아질 수 있다는 희망을 얻는다. ② *보편성*: 자신만 겪는 문제가 아님을 깨달아 고립감이 줄고 위안을 얻는다. ③ *정보전달*: 상담자·집단원에게서 문제에 관한 지식과 조언을 얻는다. ④ *이타심*: 서로 돕고 지지하는 경험에서 자존감을 회복한다. ⑤ *1차 가족집단의 교정적 재현*: 집단을 원가족처럼 경험하며 과거 가족갈등을 교정적으로 다시 다룬다. ⑥ *사회기술의 발달*: 피드백을 통해 대인관계에 필요한 사회기술을 학습한다. ⑦ *모방행동*: 상담자·다른 집단원의 적응적 행동을 관찰·모방한다. ⑧ *대인관계 학습*: 집단 상호작용에서 자기 대인패턴을 통찰·교정한다. ⑨ *집단 응집력*: 집단에 대한 소속감·신뢰가 변화의 기반이 된다. ⑩ *정화(카타르시스)*: 억압된 감정을 표현하며 정서적 해소를 경험한다. ⑪ *실존적 요인*: 삶의 유한성·책임·고독 등 실존적 조건을 직면·수용한다. | K2: 5.3 | L2: 12 | M2: 2009 2012 2013 2014 2017-1회 2017-2회 2018-1회 2019-1회 2021-1회 2024-1회 2024-3회 2026-1회 | N2: ★
A3: 2 | B3: Q118 | C3: 16.17 | D3: 5.9 | E3: B 기초심리상담 | F3: 상담관계·면접기법 | G3: 메인 | H3: 다음 보기의 내담자 진술에 대한 상담자의 반응은 각각 어떤 개입기술에 해당하는지 쓰시오. | I3: 반영 · 명료화 · 직면 · 해석 | J3: ① *반영*: 내담자의 감정을 그대로 비춰준다(“그 꿈으로 매우 놀라고 두려우셨군요”). ② *명료화*: 모호한 내용을 구체화하도록 되묻는다(“그 두려움은 어떤 죄책감을 의미하나요?”). ③ *직면*: 회피한 모순·이면을 직시하게 한다(“평소 아버지에게 갈등이 있던 것은 아닌지요?”). ④ *해석*: 무의식적 의미를 연결해 통찰을 준다(“무의식적 적개심이 상징적으로 표현된 것”). ※ 반영<명료화<직면<해석 순으로 개입 깊이가 커진다. | L3: 12 | M3: 2003 2004 2009 2013 2016-1회 2020-1회 2021-1회 2022-1회 2022-3회 2023-2회 2024-1회 2026-1회 | N3: ★
A4: 3 | B4: Q120 | C4: 10.78 | D4: 7.9 | E4: B 기초심리상담 | F4: 상담과정·목표·종결 | G4: 메인 | H4: 심리상담 과정에서 내담자가 침묵을 지키는 이유 6가지를 기술하시오. | I4: 관계형성의 두려움 · 적대감·저항 · 상담자 반응 기대 · 정서적 피로 회복 · 할 말의 부재 · 주제 제시 대기 | J4: ① *관계형성의 두려움*: 초기 단계에서 상담자와의 관계가 불안해 침묵한다. ② *적대감·저항의 표현*: 상담자에 대한 반감·저항을 침묵으로 드러낸다. ③ *상담자의 반응 기대*: 자기 말에 대한 확인·해석을 기다리며 침묵한다. ④ *정서적 피로의 회복*: 감정 표현 후 정서적 소진에서 회복하는 중이다. ⑤ *할 말의 부재*: 더 떠오르는 말이 없거나 무엇을 말할지 몰라 침묵한다. ⑥ *주제 제시 대기*: 다음 주제를 상담자가 제시해 주길 기다린다. | K4: 4 | L4: 8 | M4: 2008 2010 2012 2015 2019-1회 2023-1회 2025-1회 2026-1회 | N4: ★
A5: 4 | B5: Q71 | C5: 9.39 | D5: 9.6 | E5: A 기초심리평가 | F5: MMPI·다면적 인성검사 | G5: 메인 | H5: MMPI 상승 분석에서 4-9/9-4 형태에 대한 해석 5가지를 쓰시오. | I5: 반사회적 행동화 · 충동성·공격성 · 피상적 대인관계 · 무책임·규범 무시 · 합리화 방어 | J5: ① *반사회적·성적 행동화*: 범법·신체노출·성적 일탈 등 행동화 위험이 높다. ② *충동성·공격성*: 충동 조절이 어렵고 과격·공격적 행동을 보인다. ③ *피상적 대인관계*: 자기중심적이고 타인을 불신해 관계가 깊지 못하다. ④ *무책임·규범 무시*: 행동에 무책임하며 사회규범·가치를 무시한다. ⑤ *합리화 방어*: 합리화로 문제를 외면하고 실패 원인을 타인에게 전가한다. | K5: 5 | L5: 10 | M5: 2006 2008 2011 2015 2017-1회 2020-1회 2021-1회 2023-2회 2024-1회 2025-3회
A6: 5 | B6: Q123 | C6: 9.1 | D6: 11.3 | E6: C 심리치료 | F6: 정신역동·인간중심·이론 | G6: 메인 | H6: 방어기제의 의미를 쓰고, 방어기제 유형 5가지를 간략히 설명하시오. | I6: 자아 보호 · 무의식적 적응기제 · 억압 · 부정(부인) · 투사 · 반동형성 · 승화 | J6: (의미) *방어기제*는 불안을 일으키는 내적 갈등·외적 위협에서 *자아를 보호*하려고 *무의식적으로* 쓰는 심리적 적응 기제이다. ① *억압*: 고통스러운 생각·기억을 의식에서 무의식으로 밀어낸다. ② *부정(부인)*: 위협적 현실·감정을 없는 것처럼 여긴다. ③ *투사*: 받아들이기 어려운 자기 충동을 타인의 것으로 돌린다. ④ *반동형성*: 무의식적 충동을 정반대의 행동·태도로 표현한다. ⑤ *승화*: 용납되기 어려운 충동을 사회적으로 가치 있는 행동으로 전환한다. | L6: 10 | M6: 2004 2007 2010 2017-2회 2021-1회 2022-3회 2023-2회 2023-3회 2024-1회 2025-2회
A7: 6 | B7: Q233 | C7: 8.19 | D7: 12.8 | E7: C 심리치료 | F7: 인지·인지행동치료 | G7: 메인 | H7: 벡(Beck)의 인지적 오류 6가지를 쓰고, 각각에 대해 설명하시오. | I7: 임의적 추론 · 선택적 추상화 · 과잉일반화 · 개인화 · 이분법적 사고 · 과장/축소 · 정서적 추론 · 긍정 격하 | J7: ※ 아래 중 6가지를 골라 기술. ① *임의적 추론*: 충분한 근거 없이 결론을 내린다. ② *선택적 추상화*: 일부 정보만 보고 전체를 판단한다. ③ *과잉일반화*: 제한된 경험을 모든 상황에 적용한다. ④ *개인화*: 자신과 무관한 일을 자기 탓으로 돌린다. ⑤ *이분법적 사고*: 경험을 흑백·극단으로만 평가한다. ⑥ *과장/축소*: 사건의 중요성을 실제보다 키우거나 줄인다. ⑦ *정서적 추론*: 감정을 사실 판단의 근거로 삼는다. ⑧ *긍정 격하*: 긍정적 경험·능력을 평가절하한다. | K7: 6.3 | L7: 9 | M7: 2007 2015 2018-1회 2018-3회 2022-1회 2023-1회 2023-2회 2024-1회 2025-2회
A8: 7 | B8: Q206 | C8: 8.09 | D8: 14.3 | E8: C 심리치료 | F8: 행동치료 | G8: 메인 | H8: 행동치료기법 중 토큰 이코노미(Token Economy)의 장점을 6가지 쓰시오. | I8: 이중 강화 · 강화 포화 예방 · 지연만족 학습 · 강화 제공 간편 · 강화 지연 예방 · 개별화·체계화 | J8: ① *이중 강화 효과*: 토큰 지급과 교환강화의 이중 강화로 효과가 커진다. ② *강화 포화 예방*: 다양한 강화물로 교환돼 강화력 저하를 막는다. ③ *지연만족의 학습*: 토큰을 모으는 과정에서 만족 지연을 배운다. ④ *강화 제공의 간편성*: 바람직한 행동 직후 즉시 간편하게 줄 수 있다. ⑤ *강화 지연의 예방*: 토큰을 즉시 배분해 강화가 늦어지지 않게 한다. ⑥ *개별화·체계화 용이*: 대상별 목표행동과 교환규칙을 체계적으로 설계할 수 있다. | K8: 5 | L8: 6 | M8: 2012 2018-3회 2021-3회 2024-1회 2025-1회 2026-1회 | N8: ★
A9: 8 | B9: Q126 | C9: 7.93 | D9: 15.7 | E9: C 심리치료 | F9: 정신역동·인간중심·이론 | G9: 메인 | H9: 인간중심치료에서 로저스(Rogers)가 강조한 치료자의 특성 혹은 태도를 3가지 쓰시오. | I9: 공감적 이해 · 무조건적 긍정적 존중 · 일치성(진실성) | J9: ① *공감적 이해*: 내담자의 내적 세계를 그의 입장에서 느끼고 이해한다. ② *무조건적 긍정적 존중*: 판단 없이 내담자를 있는 그대로 수용한다. ③ *일치성(진실성)*: 상담자가 자기 경험에 솔직하고 가식 없이 대한다. | K9: 4 | L9: 11 | M9: 2008 2010 2014 2017-2회 2018-3회 2019-3회 2021-1회 2022-1회 2023-2회 2023-3회 2024-2회
A10: 9 | B10: Q178 | C10: 6.74 | D10: 16.9 | E10: B 기초심리상담 | F10: 집단상담 | G10: 메인 | H10: 집단상담의 장점과 제한점을 각각 3가지 쓰시오. | I10: 시간·비용 절감 · 현실검증 기회 · 소속감·대인학습 · 비밀보장 한계 · 개별관심 부족 · 집단압력·부적합 | J10: [장점] ① *시간·비용의 절감*: 한 번에 여러 명을 도와 효율적이다. ② *현실검증의 기회*: 축소된 사회로 기능해 자기 점검과 피드백이 가능하다. ③ *소속감·대인관계 학습*: 소속감 속에서 대인관계 문제를 다루고 학습한다. [제한점] ① *비밀보장의 한계*: 구성원이 많아 비밀유지가 어렵다. ② *개별적 관심의 부족*: 개인별 깊은 주의가 분산된다. ③ *집단 압력·부적합 위험*: 집단 압력으로 부담을 느끼거나 집단에 맞지 않아 역효과가 날 수 있다. | K10: 5.2 | L10: 5 | M10: 2015 2019-1회 2021-1회 2023-2회 2026-1회 | N10: ★
A11: 10 | B11: Q149 | C11: 6.74 | D11: 18.2 | E11: B 기초심리상담 | F11: 상담과정·목표·종결 | G11: 메인 | H11: 단회상담은 다른 일반적인 심리상담과 달리 극히 제한된 시간 내에 문제 상황을 처리해야 하는 경우 가 많다. 이러한 단회상담에서 강조되는 원리 또는 기술 7가지를 제시하시오. | I11: 단·다회 신속 결정 · 욕구 명확화 · 현실적 목표 · 능동적 대화 조절 · 융통성+단호함 · 동기 유지 · 조언·지시 활용 | J11: ① *단회/다회 신속 결정*: 단회로 끝낼지 이어갈지 신속히 판단한다. ② *원하는 바 명확화*: 내담자가 무엇을 원하는지 분명히 파악한다. ③ *현실적 목표 수립*: 함께 현실적·합리적 목표를 정한다. ④ *능동적 대화 조절*: 제한된 시간 안에서 대화를 주도적으로 이끈다. ⑤ *융통성과 단호함*: 유연하되 단호한 태도를 유지한다. ⑥ *문제해결 동기 유지*: 내담자의 해결 의지와 동기를 북돋운다. ⑦ *조언·지시의 적절한 활용*: 필요한 조언·지시를 효과적으로 활용한다. | K11: 5 | L11: 5 | M11: 2011 2015 2019-1회 2023-1회 2026-1회 | N11: ★
A12: 11 | B12: Q243 | C12: 6.74 | D12: 19.4 | E12: D 자문·교육·심리재활 | F12: 정신재활 | G12: 메인 | H12: 치료와 재활의 의미와 차이를 기술하시오. | I12: 증상·병리 완화 · 체계적 과정 · 기능 회복 · 일상 적응 · 강점·자원 활용 · 기술훈련·자원연계 | J12: (1) 의미 — *치료*는 질병·장애의 *증상·병리를 줄이거나 완화*하기 위한 계획적·체계적 활동이다. *재활*은 장애인이 *신체·정신·사회·직업적 기능을 최대한 회복*해 *일상생활에 적응*하도록 돕는 체계적 과정이다. (2) 차이 — 치료는 *원인·병리를 이해해 증상·역기능을 감소*시키는 데 초점을 둔다. 반면 재활은 *개인의 강점·자원을 활용해 기능을 회복·확장*하고 생활 적응을 돕는 *실천적 접근(기술훈련·자원연계)*에 초점을 둔다. | K12: 6 | L12: 5 | M12: 2004 2006 2007 2020-2회 2026-1회 | N12: ★
A13: 12 | B13: Q34 | C13: 6.74 | D13: 20.6 | E13: A 기초심리평가 | F13: 지능검사 | G13: 메인 | H13: 웩슬러가 정의한 지능의 개념을 쓰고 유동성 지능과 결정성 지능의 특징을 각각 2가지씩 기술하시오. | I13: 합목적적 행동 · 합리적 사고 · 환경의 효율적 처리 · 종합적·전체적 능력 · 유동성:선천·새 문제·노화감소 · 결정성:후천·언어지식·유지 | J13: (개념) 지능은 *합목적적으로 행동*하고 *합리적으로 사고*하며 *환경을 효율적으로 처리*하는 *종합적·전체적 능력*이다(웩슬러). [유동성 지능] ① *선천적·생득적*이며 뇌 성숙에 의존한다. ② *새로운 문제의 추론·처리속도*에 관여하고 *노화에 따라 감소*한다. [결정성 지능] ① *후천적 경험·교육·문화*의 산물이다. ② *언어·지식·이해* 기반으로 *연령이 들어도 유지·증가*한다. | K13: 6 | L13: 5 | M13: 2004 2010 2015 2019-3회 2026-1회 | N13: ★
A14: 13 | B14: Q7 | C14: 6.19 | D14: 21.8 | E14: A 기초심리평가 | F14: 심리평가 총론·면접·행동관찰 | G14: 메인 | H14: 초기 면담 과정에 포함되어야 할 내담자에 대한 행동관찰 요소 5가지를 쓰시오. | I14: 말과 표현 · 신체동작·면담태도 · 용모·외모 · 정서적 반응 · 이해력·의사소통능력 | J14: ① *말과 표현*: 말의 양·속도·논리성 등 언어적 특징을 관찰한다. ② *신체동작 및 면담태도*: 자세·몸짓과 협조 정도 등 태도를 관찰한다. ③ *용모 및 외모*: 위생·옷차림 등 겉모습을 관찰한다. ④ *정서적 반응*: 표정·기분과 정동이 상황에 맞는지 관찰한다. ⑤ *이해력·의사소통능력*: 질문을 알아듣고 주고받는 능력을 관찰한다. ※ 암기: “말·신·용·정·이”. | K14: 5 | L14: 7 | M14: 2003 2006 2010-1회 2013 2016-1회 2019 2025-1회
A15: 14 | B15: Q248 | C15: 6.19 | D15: 22.9 | E15: D 자문·교육·심리재활 | F15: 정신재활 | G15: 메인 | H15: 정신사회재활을 계획하고 개입할 때 재활치료의 기본 구성요소를 5가지 쓰시오. /만성 정신질환자에 대한 재활개입 방법을 3가지 쓰고, 각각에 대해 설명하시오. /학습 및 환경변화를 통해 만성 정신질 환자의 사회적 기능을 최대한 회복시키는 것을 ‘정신사회재활’이라고 한다. 정신사회재활에서 환자를 대상으로 한 치료적 개입에 포함되는 내용(구성요소)을 4가지 쓰시오. | I15: 사회기술훈련 · 환자교육(정신교육) · 가족교육·치료 · 직업재활 · 지역사회 지지서비스 | J15: ① *사회기술훈련*: 대인관계·의사소통·문제해결 등 결함된 사회기술을 학습·연습시킨다. ② *환자교육(정신교육)*: 질병 이해·약물관리·재발징후 대처를 교육해 자가관리를 높인다. ③ *가족교육 및 치료*: 가족의 이해를 높이고 역기능적 의사소통을 줄여 재발을 예방한다. ④ *직업재활*: 직업탐색·훈련·취업연계로 사회적 역할을 회복하도록 돕는다. ⑤ *지역사회 지지서비스*: 주거·재정·의료·여가 등 자원을 연결해 지역사회 적응을 돕는다. | L15: 7 | M15: 2009 2013 2016-2회 2021-1회 2021-3회 2022-1회 2025-1회
A16: 15 | B16: Q117 | C16: 5.64 | D16: 23.9 | E16: B 기초심리상담 | F16: 상담관계·면접기법 | G16: 메인 | H16: 다음 보기의 사례를 읽고 내담자의 말에 대한 반영적 반응을 적절히 제시하시오. | I16: 감정 반영 · 내용 반영 | J16: (모범 반영) “남편이 일찍 들어오겠다는 약속을 정말로 지켜서, 예상치 못한 일에 무척 놀라셨군요.” ※ 내담자의 *감정(놀람)*과 *내용(약속 이행)*을 함께 비춰주는 것이 반영의 핵심이다. | L16: 6 | M16: 2003 2005 2012 2014 2018 2025-3회
A17: 16 | B17: Q186 | C17: 5.46 | D17: 24.9 | E17: C 심리치료 | F17: 가족·아동치료 | G17: 메인 | H17: 놀이치료는 놀이 치료적 가치가 있다. 놀이의 치료적 가치를 5가지 기술하시오. | I17: 저항 감소·관계형성 · 의사소통 매체 · 불안 감소·이완 · 정화·외상 극복 · 창조적 사고·문제해결 · 유능감·자존감 · 역할놀이·행동연습 | J17: ※ 아래 중 5가지를 기술. ① *저항 감소·관계형성*: 놀이가 저항을 낮춰 치료관계 형성을 돕는다. ② *의사소통의 매체*: 말이 어려운 아동의 이해·진단 매체가 된다. ③ *불안 감소·이완*: 긴장을 풀고 불안을 줄인다. ④ *정화·외상 극복*: 놀이를 통한 정화로 심리적 외상 극복을 돕는다. ⑤ *창조적 사고·문제해결*: 창의적 사고를 촉진해 문제해결력을 높인다. ⑥ *유능감·자존감*: 성취 경험으로 자아존중감을 키운다. ⑦ *역할놀이·행동연습*: 새로운 행동을 연습·습득하게 한다. | K17: 5 | L17: 6 | M17: 2015-1회 2016-2회 2020-2회 2022-1회 2023-2회 2025-2회
A18: 17 | B18: Q193 | C18: 5.39 | D18: 25.9 | E18: C 심리치료 | F18: 가족·아동치료 | G18: 메인 | H18: 해결중심(가족)치료에서 사용하는 해결 지향적 질문 유형을 3가지 쓰고, 각각에 대해 설명하시오. | I18: 예외질문 · 기적질문 · 척도질문 · 대처질문 | J18: ※ 아래 중 3가지를 쓰고 설명. ① *예외질문*: 문제가 없었던 예외 상황을 찾아 해결 실마리를 탐색한다. ② *기적질문*: 문제가 해결된 상태를 상상하게 해 원하는 변화를 구체화한다. ③ *척도질문*: 숫자로 문제 정도·변화 수준을 평가하게 한다. ④ *대처질문*: 힘든 상황에서도 해온 대처 경험으로 강점을 인식하게 한다. | K18: 5.5 | L18: 4 | M18: 2018-1회 2020-3회 2023-3회 2026-1회 | N18: ★
A19: 18 | B19: Q92 | C19: 5.39 | D19: 26.9 | E19: A 기초심리평가 | F19: 투사검사(로샤·TAT·HTP) | G19: 메인 | H19: 로샤검사의 특수점수에서 특수내용의 종류를 3가지 쓰고 각각에 대해 설명하시오. | I19: 추상적 내용(AB) · 공격적 운동(AG) · 협조적 운동(COP) · 병적 내용(MOR) | J19: ※ 아래 중 3가지를 쓰고 설명. ① *추상적 내용(AB)*: 상징적·추상적 표현이 분명한 반응에 채점한다. ② *공격적 운동(AG)*: 싸움·파괴 등 주체적 공격이 담긴 운동반응에 채점한다. ③ *협조적 운동(COP)*: 둘 이상 대상이 적극적·협조적으로 상호작용하는 운동반응에 채점한다. ④ *병적 내용(MOR)*: 손상·죽음·우울감이 부여된 반응에 채점한다. | K19: 5.5 | L19: 4 | M19: 2018-1회 2020-3회 2023-2회 2026-1회 | N19: ★
A20: 19 | B20: Q110 | C20: 5.39 | D20: 27.9 | E20: B 기초심리상담 | F20: 상담과정·목표·종결 | G20: 메인 | H20: 상담 초기 단계에서 반드시 이루어져야 하는 내용을 3가지 쓰시오. | I20: 관계형성(라포) · 내담자 이해·평가 · 상담의 구조화 · 상담목표 설정 · 기대 조율 | J20: ※ 아래 중 3가지를 기술. ① *상담관계 형성(라포)*: 신뢰로운 작업동맹을 형성한다. ② *내담자 이해·평가*: 호소문제와 내담자를 탐색·평가한다. ③ *상담의 구조화*: 상담의 방식·역할·한계를 안내한다. ④ *상담목표 설정*: 합의된 구체적 목표를 정한다. ⑤ *기대 조율*: 상담에 대한 기대를 현실적으로 맞춘다. | K20: 5 | L20: 4 | M20: 2013 2016-1회 2023-2회 2026-1회 | N20: ★
A21: 20 | B21: Q141 | C21: 5.39 | D21: 28.9 | E21: B 기초심리상담 | F21: 상담과정·목표·종결 | G21: 메인 | H21: 상담 과정에서 내담자의 주요 호소문제가 명확해지면 상담의 구체적인 목표를 설정하게 된다. 상담 목표설정 시 지켜야 할 기준 5가지를 쓰시오. | I21: 현실성(능력 고려) · 구체성·검증가능 · 가치·욕구 부합 · 결과·성취 중심 · 측정 가능 · 시간범위 | J21: ① *현실성(능력 고려)*: 내담자의 능력에 맞춰 현실적으로 설정한다. ② *구체성·검증가능성*: 구체적 행동으로 검증 가능해야 한다. ③ *가치·욕구 부합*: 내담자의 가치와 욕구에 적절해야 한다. ④ *결과·성취 중심 진술*: 결과와 성취 중심으로 진술한다. ⑤ *측정 가능성*: 가시적이고 측정 가능한 변화로 나타나야 한다. (추가) 현실적 *시간범위*를 설정한다. | L21: 4 | M21: 2011 2017-1회 2021-3회 2026-1회 | N21: ★
A22: 21 | B22: Q240 | C22: 5.05 | D22: 29.8 | E22: D 자문·교육·심리재활 | F22: 정신재활 | G22: 메인 | H22: 재활모형에서 손상, 장애, 핸디캡의 의미를 쓰고, 개입방법상의 차이점을 설명하시오. | I22: 손상(기관·임상치료) · 장애(개인·임상재활) · 핸디캡(사회·사회재활) | J22: (1) 의미 — ① *손상*: 생리·해부학적 구조·기능에 이상이 있는 상태. ② *장애*: 손상으로 정상적 행동수행 능력이 제한·결핍된 상태. ③ *핸디캡*: 손상·장애로 역할수행이 제한돼 사회적 불이익을 겪는 상태. (2) 개입 차이 — 손상은 *기관 차원*의 약물·정신치료 등 *임상적 치료*, 장애는 *개인 차원*의 기술·역할훈련 등 *임상적 재활*, 핸디캡은 *사회 차원*의 권익옹호·편견해소·제도변화 등 *사회적 재활*로 접근한다. | K22: 5.5 | L22: 7 | M22: 2010 2012 2013 2018-1회 2023-1회 2023-2회 2024-2회
A23: 22 | B23: Q24 | C23: 4.97 | D23: 30.7 | E23: A 기초심리평가 | F23: 진단·이상심리 | G23: 메인 | H23: 심리평가의 최종 보고서에 반드시 포함되어야 할 내용을 5가지만 쓰시오. | I23: 인적사항 · 의뢰사유·주호소 · 병력·개인력·가족력 · 행동관찰·검사결과 · 진단·권고 | J23: ① *인적사항*: 이름·연령·성별 등 기본 정보. ② *의뢰사유·주호소 문제*: 평가 의뢰 이유와 핵심 호소. ③ *병력·개인력·가족력*: 현·과거 병력과 발달·가족 배경. ④ *행동관찰·검사결과*: 실시 검사 종류와 관찰·결과. ⑤ *진단적 인상·권고사항*: 의심 진단명과 치료 권고. | K23: 5 | L23: 8 | M23: 2010 2017-2회 2019-3회 2020-1회 2021-3회 2022-1회 2023-1회 2023-2회
A24: 23 | B24: Q83 | C24: 4.7 | D24: 31.6 | E24: A 기초심리평가 | F24: 기타 성격·진로검사 | G24: 메인 | H24: TCI의 척도를 구성하는 4가지 기질 차원과 3가지 성격 차원을 설명하시오. | I24: 자극추구(NS) · 위험회피(HA) · 사회적민감성(RD) · 인내력(P) · 자율성(SD) · 연대감(CO) · 자기초월(ST) | J24: [기질 4차원] ① *자극추구(NS)*: 새 자극·보상에 행동이 활성화. ② *위험회피(HA)*: 위험·혐오 자극에 행동이 억제·위축. ③ *사회적 민감성(RD)*: 사회적 보상신호(타인 감정)에 민감. ④ *인내력(P)*: 보상이 없어도 행동을 지속. [성격 3차원] ① *자율성(SD)*: 목표 위해 자기 행동을 조절·적응. ② *연대감(CO)*: 자신을 사회 일부로 보고 타인을 수용. ③ *자기초월(ST)*: 자신을 자연·우주의 일부로 느끼는 영적 성향. | L24: 5 | M24: 2018-1회 2023-3회 2024-1회 2024-3회 2025-3회
A25: 24 | B25: Q106 | C25: 4.7 | D25: 32.4 | E25: B 기초심리상담 | F25: 상담과정·목표·종결 | G25: 메인 | H25: 내담자에 대한 심리평가를 위해 사용되는 행동평가 방법 4가지를 제시하시오. | I25: 행동적 면접 · 행동관찰 · 질문지·평정척도 · 기능분석 · 자기관찰 | J25: ① *행동적 면접*: 문제행동의 선행·상황·결과(기능)를 파악한다. ② *행동관찰*: 자연·통제 상황에서 행동을 직접 관찰한다. ③ *질문지·평정척도*: 구조화된 척도로 행동·정서특성을 평가한다. ④ *기능분석*: 행동 전후 사건을 체계 분석해 원인·기능을 검증한다. (추가) *자기관찰*: 내담자가 스스로 행동을 기록·점검한다. | K25: 6 | L25: 5 | M25: 2008 2011 2019-3회 2023-2회 2025-3회
A26: 25 | B26: Q70 | C26: 4.55 | D26: 33.3 | E26: A 기초심리평가 | F26: MMPI·다면적 인성검사 | G26: 메인 | H26: MMPI-2 척도에서 6-8/8-6유형의 일반적인 특성 5가지와 가능성 있는 장애 진단명 2가지를 쓰시오. | I26: 낮은 자존감·열등감 · 적대감·의심 · 현실검증력 저하 · 정서 둔마·부적절 · 정신증 증상 · 조현병 · 분열성·편집성 성격장애 | J26: [특성 5] ① *낮은 자존감·열등감·죄책감*. ② *적대감·의심, 불안정한 대인관계*. ③ *현실검증력 저하*로 자폐적·분열적 사고. ④ *정서 둔마·부적절한 정동, 우울*. ⑤ *피해·과대망상·환청 등 정신증 증상*. [진단 2] *조현병(편집형 포함)* / *조현성(분열성)·편집성 성격장애*. | L26: 5 | M26: 2007 2010 2016-2회 2022-3회 2025-2회
A27: 26 | B27: Q133 | C27: 4.55 | D27: 34.1 | E27: B 기초심리상담 | F27: 상담윤리 | G27: 메인 | H27: 심리치료자가 내담자의 비밀을 보장할 수 없는 경우를 5가지 쓰시오. | I27: 자·타해 위험 · 감염성 질병 · 미성년 학대 피해 · 아동학대 가해 · 법적 공개 요구 | J27: ① *자·타해 위험*: 자신·타인의 생명·안전을 위협하는 경우. ② *감염성 질병*: 전염성 질병 보유가 확실한 경우. ③ *미성년자 학대 피해*: 미성년 내담자가 학대받는 경우. ④ *아동학대 가해*: 내담자가 아동학대를 가하는 경우. ⑤ *법적 공개 요구*: 법적으로 정보공개가 요구되는 경우. | L27: 5 | M27: 2011 2016 2020-3회 2024-1회 2025-2회
A28: 27 | B28: Q227 | C28: 4.55 | D28: 34.9 | E28: C 심리치료 | F28: 인지·인지행동치료 | G28: 메인 | H28: 엘리스(Ellis)가 제시한 비합리적인 신념을 5가지 쓰시오. | I28: 인정 요구 · 완벽·유능 요구 · 파국화 · 회피 신념 · 외부통제 신념 | J28: ※ 아래 중 5가지를 기술. ① *인정 요구*: 모든 중요한 사람에게 늘 사랑·인정받아야 한다. ② *완벽·유능 요구*: 모든 면에서 반드시 유능·성취해야 한다. ③ *파국화*: 바라는 대로 안 되면 끔찍한 파멸이라 여긴다. ④ *회피 신념*: 어려움에 직면하기보다 회피가 쉽다고 믿는다. ⑤ *외부통제 신념*: 불행은 외부 탓이며 스스로 통제 못한다고 본다. | K28: 5 | L28: 5 | M28: 2012 2014 2018-3회 2021-3회 2025-2회
A29: 28 | B29: Q88 | C29: 4.42 | D29: 35.7 | E29: A 기초심리평가 | F29: 투사검사(로샤·TAT·HTP) | G29: 메인 | H29: 로샤검사 엑스너 종합체계방식의 주요 채점 항목을 5가지 기술하시오. | I29: 반응영역(위치) · 결정인 · 형태질 · 반응내용 · 평범반응(P) | J29: ① *반응영역(위치)*: 반점의 어느 부분을 보았는가(W·D·Dd·S). ② *결정인*: 무엇 때문에 그렇게 보았는가(형태·운동·색채·음영). ③ *형태질*: 반응이 반점 형태에 부합하는 정도. ④ *반응내용*: 무엇으로 보았는가(인간·동물 등). ⑤ *평범반응(P)*: 흔히 나타나는 전형적 반응 여부. | K29: 5 | L29: 5 | M29: 2015 2020-1회 2023-1회 2024-1회 2025-1회
A30: 29 | B30: Q189 | C30: 4.04 | D30: 36.5 | E30: C 심리치료 | F30: 정신역동·인간중심·이론 | G30: 메인 | H30: 정신역동적 치료의 특징을 5가지 쓰시오. | I30: 정서 표현 초점 · 과거경험 영향 · 반복되는 대인관계 양상 · 치료관계 중시 · 무의식 갈등 통찰 · 성격구조 변화 | J30: ① *정서·감정 표현에 초점*을 둔다. ② *과거 경험이 현재에 미치는 영향*을 강조한다. ③ *반복되는 대인관계 양상*에 주목한다. ④ *치료적 관계*를 변화의 핵심으로 본다. ⑤ *무의식적 동기·갈등의 통찰*을 돕는다. (추가) 증상보다 *성격구조의 변화*를 중시한다. | K30: 5 | L30: 3 | M30: 2020-2회 2025-1회 2026-1회 | N30: ★
A31: 30 | B31: Q74 | C31: 4.04 | D31: 37.2 | E31: A 기초심리평가 | F31: MMPI·다면적 인성검사 | G31: 메인 | H31: MMPI-2의 성격병리 5요인 척도(PSY-5 척도)를 쓰시오. | I31: 공격성(AGGR) · 정신증(PSYC) · 통제결여(DISC) · 부정적 정서성/신경증(NEGE) · 내향성/낮은 긍정정서(INTR) | J31: ① *공격성(AGGR)* ② *정신증(PSYC)* ③ *통제결여(DISC)* ④ *부정적 정서성/신경증(NEGE)* ⑤ *내향성/낮은 긍정적 정서성(INTR)* | K31: 5 | L31: 3 | M31: 2018-3회 2021-3회 2026-1회 | N31: ★
A32: 31 | B32: Q168 | C32: 4.04 | D32: 38 | E32: B 기초심리상담 | F32: 상담관계·면접기법 | G32: 메인 | H32: 다음 보기의 사례를 읽고 물음에 답하시오. | I32: 명료화 · 직면 | J32: (1) *명료화*: “꿈이지만 아버지를 잘못 쏘았다는 상황에서 강한 죄책감을 느꼈다는 의미인가요?” — 모호한 감정을 구체화한다. (2) *직면*: “평소 권위적이라 느낀 아버지에 대한 미움이 이 꿈에 반영된 건 아닐까요?” — 회피된 감정을 직시하게 한다. | L32: 3 | M32: 2017-2회 2020-1회 2026-1회 | N32: ★
A33: 32 | B33: Q19 | C33: 3.76 | D33: 38.6 | E33: B 기초심리상담 | F33: 상담과정·목표·종결 | G33: 메인 | H33: (임상적) 접수 면접에서 반드시 확인되어야 할 내용 5가지를 쓰시오. | I33: 인적사항 · 호소문제 · 현재 기능상태 · 스트레스 원인 · 사회·심리적 자원 · 개인사·가족관계 | J33: ① *인적사항(기본 정보)*. ② *호소 문제*. ③ *현재·최근의 기능 상태*. ④ *스트레스의 원인*. ⑤ *사회적·심리적 지원 자원*. (추가) 호소 관련 *개인사·가족관계*, *외모·행동*. | K33: 5 | L33: 4 | M33: 2016-2회 2020-2회 2024-1회 2025-3회
A34: 33 | B34: Q139 | C34: 3.76 | D34: 39.3 | E34: C 심리치료 | F34: 정신역동·인간중심·이론 | G34: 메인 | H34: 실존치료에서는 정상적 불안과 신경증적 불안을 구분하고 있다. 그 중 정상적 불안의 특징을 3가지 쓰시오. | I34: 상황에 부합 · 억압 불필요 · 창조적 활용 가능 | J34: ① *상황에 부합되는* 불안이다. ② *억압을 요구하지 않는* 불안이다. ③ *창조적으로 활용 가능한* 불안이다. (↔ 신경증적 불안: 상황에 부적합·억압됨·파괴적) | K34: 5 | L34: 4 | M34: 2016-2회 2019-1회 2024-2회 2025-3회
A35: 34 | B35: Q148 | C35: 3.76 | D35: 40 | E35: B 기초심리상담 | F35: 상담과정·목표·종결 | G35: 메인 | H35: 단기상담에 적합한 내담자의 특성 5가지를 기술하시오. | I35: 구체적 호소문제 · 이전 기능 양호 · 사회적 지지자원 · 심각한 병리 없음 · 문제 인식 명확 · 발달적·일시적 문제 | J35: ① *호소문제가 구체적*이다. ② 문제 이전 *생활기능이 양호*했다. ③ *사회적 지지자원*이 있다. ④ *성격장애 등 심각한 병리가 없다*. ⑤ *자기 문제를 비교적 명확히 인식*한다. (추가) 발달·일시적 사건과 관련된 문제. | K35: 4 | L35: 4 | M35: 2015 2018-1회 2023-2회 2025-3회
A36: 35 | B36: Q215 | C36: 3.76 | D36: 40.7 | E36: C 심리치료 | F36: 행동치료 | G36: 메인 | H36: 체계적 둔감법(Systematic Desensitization)의 원리 및 시행순서를 쓰고 설명하시오. | I36: 상호억제(역조건형성) · 이완훈련 · 불안위계 작성 · 점진적 둔감화(노출) | J36: (원리) 고전적 조건형성의 *상호억제(역조건형성)* 원리로, 불안과 양립할 수 없는 *이완 반응*으로 불안을 억제한다. (순서) ① *이완훈련* → ② *불안 위계목록 작성* → ③ *위계에 따른 점진적 둔감화(노출)*. | L36: 4 | M36: 2015 2018-1회 2019-3회 2025-3회
A37: 36 | B37: Q245 | C37: 3.76 | D37: 41.4 | E37: D 자문·교육·심리재활 | F37: 정신재활 | G37: 메인 | H37: 만성 정신과 환자가 있는 가족이 환자의 치료와 재활과정을 돕는 방법 5가지와 피해야할 태도 5가지 를 쓰시오. | I37: 치료지속 지지 · 약물복용 격려 · 권익 대변 · 차분한 분위기 · 현실적 기대 · 과잉개입 · 비판·잔소리(높은 표출정서) · 따돌림 · 호전 당연시 · 조기 호전 기대 | J37: [돕는 방법 5] ① *치료·재활 지속 지지*. ② *약물 복용 격려(재발 방지)*. ③ *환자 입장 대변(권익옹호)*. ④ *차분·인내하는 분위기 유지*. ⑤ *기대치를 현실적 수준으로 조정*. [피해야 할 태도 5] ① *과잉개입·과보호*. ② *잔소리·비판적 어투(높은 표출정서 EE)*. ③ *따돌림·고립*. ④ *작은 호전을 당연시*. ⑤ *조기 호전을 기대*. | L37: 4 | M37: 2005 2014 2020-1회 2025-3회
A38: 37 | B38: Q108 | C38: 3.64 | D38: 42.1 | E38: A 기초심리평가 | F38: 기타 성격·진로검사 | G38: 메인 | H38: 사회성숙도 검사에서 아동발달의 측정영역 6가지를 기술하시오. | I38: 자조 · 이동 · 작업 · 의사소통 · 자기관리 · 사회화 | J38: ① *자조영역* ② *이동영역* ③ *작업영역* ④ *의사소통영역* ⑤ *자기관리영역* ⑥ *사회화영역* (사회성숙도검사 SMS의 6개 측정영역) | L38: 4 | M38: 2015 2022-3회 2024-1회 2025-2회
A39: 38 | B39: Q121 | C39: 3.62 | D39: 42.7 | E39: B 기초심리상담 | F39: 상담관계·면접기법 | G39: 메인 | H39: 내담자의 반응을 해석할 때의 주의사항 5가지를 제시하시오. | I39: 수용 준비 시 사용 · 근거 없으면 자제 · 반영→명료화→직면→해석 순서 · 즉각·충고적 해석 회피 · 가설 형태 제시 | J39: ① *수용 준비가 됐을 때* 조심스럽게 사용한다. ② *성격 파악·실증 근거가 없으면* 해석을 삼간다. ③ *초기 반영 → 중기 명료화·직면 → 후기 해석* 순서를 지킨다. ④ *즉각적·충고적 해석은 피한다*. ⑤ *단정 대신 가능성·가설 형태*로 제시해 스스로 깨닫게 한다. | K39: 5 | L39: 7 | M39: 2006 2008 2011 2015 2018-3회 2020-3회 2021-3회
A40: 39 | B40: Q67 | C40: 3.54 | D40: 43.4 | E40: A 기초심리평가 | F40: MMPI·다면적 인성검사 | G40: 메인 | H40: 타당도 척도 L, K 30 이하/ F 70 이상일 때 유형 2가지를 쓰시오. | I40: 곤란 인정·해결능력 결여 · 증상 과장·위장(부정왜곡) | J40: ① *곤란 인정·해결능력 결여*: 정서·신체적 곤란은 인정하나 스스로 해결할 자신·능력이 없다. ② *증상 과장·위장*: 도움을 얻으려 증상을 과장하거나 장애가 있는 듯 위장한다(부정왜곡/‘fake-bad’). | L40: 4 | M40: 2015-1회 2019-3회 2020-1회 2025-1회
...

Sheet 회차별
A1: 회차 | B1: 연도 | C1: Q번호 | D1: 세부단원 | E1: 구분 | F1: 문제 | G1: 평균배점 | H1: 가중치
A2: 1985 | B2: 1985 | C2: Q150 | D2: 상담윤리 | E2: 확장 | F2: Kadushin | H2: 1.35
A3: 3 | B3: 2003 | C3: Q118 | D3: 상담관계·면접기법 | E3: 메인 | F3: 다음 보기의 내담자 진술에 대한 상담자의 반응은 각각 어떤 개입기술에 해당하는지 쓰시오. | H3: 16.17
A4: 3 | B4: 2003 | C4: Q7 | D4: 심리평가 총론·면접·행동관찰 | E4: 메인 | F4: 초기 면담 과정에 포함되어야 할 내담자에 대한 행동관찰 요소 5가지를 쓰시오. | G4: 5 | H4: 6.19
A5: 3 | B5: 2003 | C5: Q117 | D5: 상담관계·면접기법 | E5: 메인 | F5: 다음 보기의 사례를 읽고 내담자의 말에 대한 반영적 반응을 적절히 제시하시오. | H5: 5.64
A6: 3 | B6: 2003 | C6: Q161 | D6: 건강심리·중독·스트레스 | E6: 메인 | F6: 최근 인터넷 중독이 사회적인 관심으로 대두되고 있다. 인터넷 중독이 의심되는 내담자로 하여금 인 터넷 중독에서 벗어날 수 있도록 일반적으로 추천하는 방법을 5가지만 쓰시오. | H6: 3.38
A7: 3 | B7: 2003 | C7: Q115 | D7: 상담과정·목표·종결 | E7: 메인 | F7: 다음은 상담 초기에 흔히 볼 수 있는 대화이다. 보기에서 내담자는 상담의 효과에 대한 의문과 회의 를 표명하였다. 이와 같은 경우 상담자는 어떻게 반응해야 하며, 그러한 반응의 근거는 무엇인지 설 명하시오. | H7: 2.82
A8: 3 | B8: 2003 | C8: Q31 | D8: 심리평가 총론·면접·행동관찰 | E8: 메인 | F8: 아동 및 청소년을 대상으로 한 상담에서는 발달적 측면에 대한 고려가 이루어져야 한다. 피아제 (Piaget)의 인지발달 이론에 의한 발달단계에서 전조작기, 구체적 조작기, 형식적 조작기에 해당하는 아동 및 청소년을 위한 상담의 특성 및 주의사항을 발달 단계별로 쓰시오. | G8: 6 | H8: 2.46
A9: 3 | B9: 2003 | C9: Q22 | D9: 검사이론·해석·보고서 | E9: 메인 | F9: 임상 면접의 서면보고서에 포함되어야 할 사항 5가지를 쓰시오. | G9: 5 | H9: 2.29
A10: 3 | B10: 2003 | C10: Q244 | D10: 자문·임상가 역할·수련 | E10: 메인 | F10: 다음의 사례를 읽고 당신은 임상심리사로서 A씨와 같이 정신질환을 가진 사람들을 모아서 정신 재활 프로그램을 운영하고자 한다. 이러한 정신 재활에 있어서 가장 기본적인 원리에 해당하는 5가지를 기 술하시오. | H10: 2.21
A11: 3 | B11: 2003 | C11: Q68 | D11: MMPI·다면적 인성검사 | E11: 메인 | F11: MMPI 6번 척도가 T 점수 72점이 나왔다면 이는 임상적으로 어떤 의미인지 5가지를 제시하시오. | G11: 5 | H11: 1.91
A12: 3 | B12: 2003 | C12: Q82 | D12: 지능검사 | E12: 확장 | F12: 다음 사례를 읽고 검사결과 해석을 쓰시오. | H12: 1.66
A13: 4 | B13: 2004 | C13: Q118 | D13: 상담관계·면접기법 | E13: 메인 | F13: 다음 보기의 내담자 진술에 대한 상담자의 반응은 각각 어떤 개입기술에 해당하는지 쓰시오. | H13: 16.17
A14: 4 | B14: 2004 | C14: Q123 | D14: 정신역동·인간중심·이론 | E14: 메인 | F14: 방어기제의 의미를 쓰고, 방어기제 유형 5가지를 간략히 설명하시오. | H14: 9.1
A15: 4 | B15: 2004 | C15: Q243 | D15: 정신재활 | E15: 메인 | F15: 치료와 재활의 의미와 차이를 기술하시오. | G15: 6 | H15: 6.74
A16: 4 | B16: 2004 | C16: Q34 | D16: 지능검사 | E16: 메인 | F16: 웩슬러가 정의한 지능의 개념을 쓰고 유동성 지능과 결정성 지능의 특징을 각각 2가지씩 기술하시오. | G16: 6 | H16: 6.74
A17: 4 | B17: 2004 | C17: Q154 | D17: 진단·이상심리 | E17: 메인 | F17: 다음 보기의 사례를 읽고 물음에 답하시오. | H17: 3.32
A18: 4 | B18: 2004 | C18: Q33 | D18: 검사이론·해석·보고서 | E18: 메인 | F18: 타당도의 개념 및 종류에 대해 설명하시오. | H18: 2.7
A19: 4 | B19: 2004 | C19: Q239 | D19: 집단상담 | E19: 확장 | F19: 다음 보기의 사례를 읽고 물음에 답하시오. | H19: 1.31
A20: 4 | B20: 2004 | C20: Q153 | D20: 신경심리·뇌손상 | E20: 확장 | F20: 다음 보기의 사례를 읽고 물음에 답하시오. | H20: 1.13
A21: 4 | B21: 2004 | C21: Q50 | D21: 지능검사 | E21: 확장 | F21: 웩슬러 지능검사의 결과를 통해 나타나는 우울증의 특징 5가지를 쓰시오. | G21: 4.7 | H21: 0.69
A22: 4 | B22: 2004 | C22: Q160 | D22: 건강심리·중독·스트레스 | E22: 확장 | F22: 인터넷 중독의 증후를 6가지만 쓰시오. | H22: 0.67
A23: 4 | B23: 2004 | C23: Q163 | D23: 신경심리·뇌손상 | E23: 확장 | F23: DSM-5 분류상 알츠하이머병으로 인한 주요 또는 경도 신경인지장애의 주요 증상 4가지를 기술하시 오. | H23: 0.31
A24: 5 | B24: 2005 | C24: Q117 | D24: 상담관계·면접기법 | E24: 메인 | F24: 다음 보기의 사례를 읽고 내담자의 말에 대한 반영적 반응을 적절히 제시하시오. | H24: 5.64
A25: 5 | B25: 2005 | C25: Q245 | D25: 정신재활 | E25: 메인 | F25: 만성 정신과 환자가 있는 가족이 환자의 치료와 재활과정을 돕는 방법 5가지와 피해야할 태도 5가지 를 쓰시오. | H25: 3.76
A26: 5 | B26: 2005 | C26: Q209 | D26: 인지·인지행동치료 | E26: 메인 | F26: 다음 보기의 사례를 읽고 물음에 답하시오. | H26: 2.82
A27: 5 | B27: 2005 | C27: Q244 | D27: 자문·임상가 역할·수련 | E27: 메인 | F27: 다음의 사례를 읽고 당신은 임상심리사로서 A씨와 같이 정신질환을 가진 사람들을 모아서 정신 재활 프로그램을 운영하고자 한다. 이러한 정신 재활에 있어서 가장 기본적인 원리에 해당하는 5가지를 기 술하시오. | H27: 2.21
A28: 5 | B28: 2005 | C28: Q26 | D28: 검사이론·해석·보고서 | E28: 메인 | F28: 심리학적 평가보고서를 작성할 때 심리검사 결과와 생활사적 정보 통합이 중요한 이유를 기술하시오. | H28: 1.94
A29: 5 | B29: 2005 | C29: Q68 | D29: MMPI·다면적 인성검사 | E29: 메인 | F29: MMPI 6번 척도가 T 점수 72점이 나왔다면 이는 임상적으로 어떤 의미인지 5가지를 제시하시오. | G29: 5 | H29: 1.91
A30: 5 | B30: 2005 | C30: Q11 | D30: 검사이론·해석·보고서 | E30: 확장 | F30: 총집검사(Full Battery)를 실시하는 이유 2가지를 기술하시오. | H30: 0.32
A31: 5 | B31: 2005 | C31: Q32 | D31: 검사이론·해석·보고서 | E31: 확장 | F31: 표준화 검사에서 흔히 사용되는 원점수와 백분위 점수, Z점수, T점수 간의 관계를 중앙 집중치와 분 산의 관점에서 비교하고 흔히 검사결과에서는 어떠한 수준을 이상으로 간주하는가에 대해 설명하시오. | H31: 0.32
A32: 5 | B32: 2005 | C32: Q80 | D32: MMPI·다면적 인성검사 | E32: 확장 | F32: 다음 사례의 MMPI 검사결과에서 유추되는 임상적 특징 5가지를 기술하시오. | G32: 4 | H32: 0.32
A33: 6 | B33: 2006 | C33: Q71 | D33: MMPI·다면적 인성검사 | E33: 메인 | F33: MMPI 상승 분석에서 4-9/9-4 형태에 대한 해석 5가지를 쓰시오. | G33: 5 | H33: 9.39
A34: 6 | B34: 2006 | C34: Q243 | D34: 정신재활 | E34: 메인 | F34: 치료와 재활의 의미와 차이를 기술하시오. | G34: 6 | H34: 6.74
A35: 6 | B35: 2006 | C35: Q7 | D35: 심리평가 총론·면접·행동관찰 | E35: 메인 | F35: 초기 면담 과정에 포함되어야 할 내담자에 대한 행동관찰 요소 5가지를 쓰시오. | G35: 5 | H35: 6.19
A36: 6 | B36: 2006 | C36: Q121 | D36: 상담관계·면접기법 | E36: 메인 | F36: 내담자의 반응을 해석할 때의 주의사항 5가지를 제시하시오. | G36: 5 | H36: 3.62
A37: 6 | B37: 2006 | C37: Q161 | D37: 건강심리·중독·스트레스 | E37: 메인 | F37: 최근 인터넷 중독이 사회적인 관심으로 대두되고 있다. 인터넷 중독이 의심되는 내담자로 하여금 인 터넷 중독에서 벗어날 수 있도록 일반적으로 추천하는 방법을 5가지만 쓰시오. | H37: 3.38
A38: 6 | B38: 2006 | C38: Q112 | D38: 상담관계·면접기법 | E38: 메인 | F38: 내담자의 말을 경청하는 데 있어서 좋은 상담자가 되기 위한 구체적인 방법 5가지를 쓰시오. (생산적 인 경청을 하는 상담자의 태도, 효과적 경청을 위한 행동) | H38: 3.11
A39: 6 | B39: 2006 | C39: Q128 | D39: 상담윤리 | E39: 메인 | F39: 상담자가 상담시 내담자와의 관계에 대해 알고 있어야 할 윤리 문제에 대한 기본원칙을 쓰고, 행동지 침을 5가지 기술하시오. | G39: 7 | H39: 3.06
A40: 6 | B40: 2006 | C40: Q115 | D40: 상담과정·목표·종결 | E40: 메인 | F40: 다음은 상담 초기에 흔히 볼 수 있는 대화이다. 보기에서 내담자는 상담의 효과에 대한 의문과 회의 를 표명하였다. 이와 같은 경우 상담자는 어떻게 반응해야 하며, 그러한 반응의 근거는 무엇인지 설 명하시오. | H40: 2.82
...

Sheet 단원요약
A1: 영역 | B1: 세부단원 | C1: 총문항 | D1: 메인 | E1: 확장 | F1: 검토필요
A2: A 기초심리평가 | B2: MMPI·다면적 인성검사 | C2: =COUNTIF(단원별DB!B:B,B2) | D2: =COUNTIFS(단원별DB!B:B,B2,단원별DB!C:C,"메인") | E2: =COUNTIFS(단원별DB!B:B,B2,단원별DB!C:C,"확장") | F2: =COUNTIFS(단원별DB!B:B,B2,단원별DB!L:L,"검토필요")
A3: A 기초심리평가 | B3: 기타 성격·진로검사 | C3: =COUNTIF(단원별DB!B:B,B3) | D3: =COUNTIFS(단원별DB!B:B,B3,단원별DB!C:C,"메인") | E3: =COUNTIFS(단원별DB!B:B,B3,단원별DB!C:C,"확장") | F3: =COUNTIFS(단원별DB!B:B,B3,단원별DB!L:L,"검토필요")
A4: A 기초심리평가 | B4: 지능검사 | C4: =COUNTIF(단원별DB!B:B,B4) | D4: =COUNTIFS(단원별DB!B:B,B4,단원별DB!C:C,"메인") | E4: =COUNTIFS(단원별DB!B:B,B4,단원별DB!C:C,"확장") | F4: =COUNTIFS(단원별DB!B:B,B4,단원별DB!L:L,"검토필요")
A5: A 기초심리평가 | B5: 신경심리·뇌손상 | C5: =COUNTIF(단원별DB!B:B,B5) | D5: =COUNTIFS(단원별DB!B:B,B5,단원별DB!C:C,"메인") | E5: =COUNTIFS(단원별DB!B:B,B5,단원별DB!C:C,"확장") | F5: =COUNTIFS(단원별DB!B:B,B5,단원별DB!L:L,"검토필요")
A6: A 기초심리평가 | B6: 투사검사(로샤·TAT·HTP) | C6: =COUNTIF(단원별DB!B:B,B6) | D6: =COUNTIFS(단원별DB!B:B,B6,단원별DB!C:C,"메인") | E6: =COUNTIFS(단원별DB!B:B,B6,단원별DB!C:C,"확장") | F6: =COUNTIFS(단원별DB!B:B,B6,단원별DB!L:L,"검토필요")
A7: A 기초심리평가 | B7: 심리평가 총론·면접·행동관찰 | C7: =COUNTIF(단원별DB!B:B,B7) | D7: =COUNTIFS(단원별DB!B:B,B7,단원별DB!C:C,"메인") | E7: =COUNTIFS(단원별DB!B:B,B7,단원별DB!C:C,"확장") | F7: =COUNTIFS(단원별DB!B:B,B7,단원별DB!L:L,"검토필요")
A8: A 기초심리평가 | B8: 검사이론·해석·보고서 | C8: =COUNTIF(단원별DB!B:B,B8) | D8: =COUNTIFS(단원별DB!B:B,B8,단원별DB!C:C,"메인") | E8: =COUNTIFS(단원별DB!B:B,B8,단원별DB!C:C,"확장") | F8: =COUNTIFS(단원별DB!B:B,B8,단원별DB!L:L,"검토필요")
A9: A 기초심리평가 | B9: 진단·이상심리 | C9: =COUNTIF(단원별DB!B:B,B9) | D9: =COUNTIFS(단원별DB!B:B,B9,단원별DB!C:C,"메인") | E9: =COUNTIFS(단원별DB!B:B,B9,단원별DB!C:C,"확장") | F9: =COUNTIFS(단원별DB!B:B,B9,단원별DB!L:L,"검토필요")
A10: B 기초심리상담 | B10: 상담관계·면접기법 | C10: =COUNTIF(단원별DB!B:B,B10) | D10: =COUNTIFS(단원별DB!B:B,B10,단원별DB!C:C,"메인") | E10: =COUNTIFS(단원별DB!B:B,B10,단원별DB!C:C,"확장") | F10: =COUNTIFS(단원별DB!B:B,B10,단원별DB!L:L,"검토필요")
A11: B 기초심리상담 | B11: 상담과정·목표·종결 | C11: =COUNTIF(단원별DB!B:B,B11) | D11: =COUNTIFS(단원별DB!B:B,B11,단원별DB!C:C,"메인") | E11: =COUNTIFS(단원별DB!B:B,B11,단원별DB!C:C,"확장") | F11: =COUNTIFS(단원별DB!B:B,B11,단원별DB!L:L,"검토필요")
A12: B 기초심리상담 | B12: 상담윤리 | C12: =COUNTIF(단원별DB!B:B,B12) | D12: =COUNTIFS(단원별DB!B:B,B12,단원별DB!C:C,"메인") | E12: =COUNTIFS(단원별DB!B:B,B12,단원별DB!C:C,"확장") | F12: =COUNTIFS(단원별DB!B:B,B12,단원별DB!L:L,"검토필요")
A13: B 기초심리상담 | B13: 집단상담 | C13: =COUNTIF(단원별DB!B:B,B13) | D13: =COUNTIFS(단원별DB!B:B,B13,단원별DB!C:C,"메인") | E13: =COUNTIFS(단원별DB!B:B,B13,단원별DB!C:C,"확장") | F13: =COUNTIFS(단원별DB!B:B,B13,단원별DB!L:L,"검토필요")
... A20: D 자문·교육·심리재활 | B20: 건강심리·중독·스트레스 | C20: =COUNTIF(단원별DB!B:B,B20) | D20: =COUNTIFS(단원별DB!B:B,B20,단원별DB!C:C,"메인") | E20: =COUNTIFS(단원별DB!B:B,B20,단원별DB!C:C,"확장") | F20: =COUNTIFS(단원별DB!B:B,B20,단원별DB!L:L,"검토필요")
B21: 합계 | C21: =SUM(C2:C20) | D21: =SUM(D2:D20) | E21: =SUM(E2:E20) | F21: =SUM(F2:F20)
